Workbook

Sheet Master_Data_Features
B2: Feature_ID | C2: Feature_Name | D2: Agent_Type | E2: Category | F2: Quarter_Planned | G2: Replicability_Score | H2: Primary_Client | I2: Additional_Clients | J2: Platform_vs_Custom | K2: ARR_Amount | L2: Revenue_Type | M2: Contract_Status | N2: Pipeline_Stage | O2: Conversion_Probability_% | P2: Current_Status | Q2: Completion_% | R2: Target_Completion_Date | S2: Effort_Estimate_Weeks | T2: Revenue_at_Risk | U2: Priority_Score | V2: Engineering_Notes | W2: Management_Notes | X2: Client_Count | Y2: Deal_Close_Date | Z2: Days_to_Close | AA2: Multi_Client_Benefit | AB2: Effort_Estimate_Weeks | AC2: Effort_T-Shirt_Size | AD2: Engineering_Complexity | AE2: Dependencies | AF2: Team_Required | AG2: Priority_Score | AH2: Priority_Tier | AI2: Revenue_Impact_Type | AJ2: Weighted_ARR | AK2: Assigned_To | AL2: Sprint_Assignment | AM2: JIRA_Ticket_Count | AN2: Created_Date | AO2: Target_Start_Date | AP2: Sales_Notes | AQ2: Manual_Override | AR2: Manual_Override_Score | AS2: Artemis_Focus | AT2: PRD_Status | AU2: Epic_in_JIRA
B3: F-001 | C3: LLM-Enhanced Extraction | D3: Platform (All Agents) | E3: Platform Improvements | F3: Q4 2025 | G3: 5 | H3: Multiple | I3: 0 | J3: Platform Enhancement | X3: =IF(H3="Multiple",IF(ISBLANK(I3),1,LEN(I3)-LEN(SUBSTITUTE(I3,",",""))+1),IF(NOT(ISBLANK(I3)),LEN(I3)-LEN(SUBSTITUTE(I3,",",""))+2,1)) -> 1 | Z3: =IF(NOT(ISBLANK(Y3)),Y3-TODAY(),"") | AG3: =IF(AND(NOT(ISBLANK(K3)),NOT(ISBLANK(G3)),NOT(ISBLANK(O3)),NOT(ISBLANK(AB3)),AB3>0),(K3*G3*(O3/100))/AB3,0) -> 0 | AH3: =IF(T3="Yes","Tier 0: Emergency",IF(AG3>=100,"Tier 1: Fast Track",IF(AG3>=50,"Tier 2: Standard Delivery",IF(AG3>=10,"Tier 3: Custom Engagement","Tier 4: Backlog")))) -> Tier 4: Backlog | AI3: =IF(T3="Yes","Negative (Risk of Loss)",IF(L3="Retention/Risk of Loss","Negative (Risk of Loss)",IF(AND(K3>0,OR(L3="New Contract",L3="Expansion")),"Positive (New Revenue)","Neutral (Internal/Platform)"))) -> Neutral (Internal/Platform) | AJ3: =IF(NOT(ISBLANK(K3)),K3*(O3/100),0) -> 0 | AP3: =COUNTIF(Master_Data_JIRA_Tickets!I:I,B3) -> 0 | AS3: Yes | AT3: In Progress | AU3: Yes
B4: F-002 | C4: Client Agent Interaction Enhancements | D4: Platform (All Agents) | E4: Platform Improvements | F4: Q4 2025 | G4: 5 | H4: Multiple | I4: 0 | J4: Platform Enhancement | X4: =IF(H4="Multiple",IF(ISBLANK(I4),1,LEN(I4)-LEN(SUBSTITUTE(I4,",",""))+1),IF(NOT(ISBLANK(I4)),LEN(I4)-LEN(SUBSTITUTE(I4,",",""))+2,1)) -> 1 | Z4: =IF(NOT(ISBLANK(Y4)),Y4-TODAY(),"") | AG4: =IF(AND(NOT(ISBLANK(K4)),NOT(ISBLANK(G4)),NOT(ISBLANK(O4)),NOT(ISBLANK(AB4)),AB4>0),(K4*G4*(O4/100))/AB4,0) -> 0 | AH4: =IF(T4="Yes","Tier 0: Emergency",IF(AG4>=100,"Tier 1: Fast Track",IF(AG4>=50,"Tier 2: Standard Delivery",IF(AG4>=10,"Tier 3: Custom Engagement","Tier 4: Backlog")))) -> Tier 4: Backlog | AI4: =IF(T4="Yes","Negative (Risk of Loss)",IF(L4="Retention/Risk of Loss","Negative (Risk of Loss)",IF(AND(K4>0,OR(L4="New Contract",L4="Expansion")),"Positive (New Revenue)","Neutral (Internal/Platform)"))) -> Neutral (Internal/Platform) | AJ4: =IF(NOT(ISBLANK(K4)),K4*(O4/100),0) -> 0 | AP4: =COUNTIF(Master_Data_JIRA_Tickets!I:I,B4) -> 0 | AS4: No | AT4: Not Started | AU4: No
B5: F-003 | C5: DeepSee Service Fabric Internal Enhancements | D5: Platform (All Agents) | E5: Core Infrastructure | F5: Q4 2025 | G5: 5 | H5: Internal | I5: 0 | J5: Platform Enhancement | X5: =IF(H5="Multiple",IF(ISBLANK(I5),1,LEN(I5)-LEN(SUBSTITUTE(I5,",",""))+1),IF(NOT(ISBLANK(I5)),LEN(I5)-LEN(SUBSTITUTE(I5,",",""))+2,1)) -> 2 | Z5: =IF(NOT(ISBLANK(Y5)),Y5-TODAY(),"") | AG5: =IF(AND(NOT(ISBLANK(K5)),NOT(ISBLANK(G5)),NOT(ISBLANK(O5)),NOT(ISBLANK(AB5)),AB5>0),(K5*G5*(O5/100))/AB5,0) -> 0 | AH5: =IF(T5="Yes","Tier 0: Emergency",IF(AG5>=100,"Tier 1: Fast Track",IF(AG5>=50,"Tier 2: Standard Delivery",IF(AG5>=10,"Tier 3: Custom Engagement","Tier 4: Backlog")))) -> Tier 4: Backlog | AI5: =IF(T5="Yes","Negative (Risk of Loss)",IF(L5="Retention/Risk of Loss","Negative (Risk of Loss)",IF(AND(K5>0,OR(L5="New Contract",L5="Expansion")),"Positive (New Revenue)","Neutral (Internal/Platform)"))) -> Neutral (Internal/Platform) | AJ5: =IF(NOT(ISBLANK(K5)),K5*(O5/100),0) -> 0 | AP5: =COUNTIF(Master_Data_JIRA_Tickets!I:I,B5) -> 0 | AS5: No | AT5: Not Started | AU5: No
B6: F-004 | C6: Retention Prediction UI | D6: Platform (Analytics) | E6: Platform Improvements | F6: Q4 2025 | G6: 5 | H6: Multiple | I6: 0 | J6: Platform Enhancement | X6: =IF(H6="Multiple",IF(ISBLANK(I6),1,LEN(I6)-LEN(SUBSTITUTE(I6,",",""))+1),IF(NOT(ISBLANK(I6)),LEN(I6)-LEN(SUBSTITUTE(I6,",",""))+2,1)) -> 1 | Z6: =IF(NOT(ISBLANK(Y6)),Y6-TODAY(),"") | AG6: =IF(AND(NOT(ISBLANK(K6)),NOT(ISBLANK(G6)),NOT(ISBLANK(O6)),NOT(ISBLANK(AB6)),AB6>0),(K6*G6*(O6/100))/AB6,0) -> 0 | AH6: =IF(T6="Yes","Tier 0: Emergency",IF(AG6>=100,"Tier 1: Fast Track",IF(AG6>=50,"Tier 2: Standard Delivery",IF(AG6>=10,"Tier 3: Custom Engagement","Tier 4: Backlog")))) -> Tier 4: Backlog | AI6: =IF(T6="Yes","Negative (Risk of Loss)",IF(L6="Retention/Risk of Loss","Negative (Risk of Loss)",IF(AND(K6>0,OR(L6="New Contract",L6="Expansion")),"Positive (New Revenue)","Neutral (Internal/Platform)"))) -> Neutral (Internal/Platform) | AJ6: =IF(NOT(ISBLANK(K6)),K6*(O6/100),0) -> 0 | AP6: =COUNTIF(Master_Data_JIRA_Tickets!I:I,B6) -> 0 | AS6: No | AT6: Not Started | AU6: No
B7: F-005 | C7: Double-click to view dashboard messages | D7: Platform (Analytics) | E7: Platform Improvements | F7: Q4 2025 | G7: 5 | H7: Multiple | I7: 0 | J7: Platform Enhancement | X7: =IF(H7="Multiple",IF(ISBLANK(I7),1,LEN(I7)-LEN(SUBSTITUTE(I7,",",""))+1),IF(NOT(ISBLANK(I7)),LEN(I7)-LEN(SUBSTITUTE(I7,",",""))+2,1)) -> 1 | Z7: =IF(NOT(ISBLANK(Y7)),Y7-TODAY(),"") | AG7: =IF(AND(NOT(ISBLANK(K7)),NOT(ISBLANK(G7)),NOT(ISBLANK(O7)),NOT(ISBLANK(AB7)),AB7>0),(K7*G7*(O7/100))/AB7,0) -> 0 | AH7: =IF(T7="Yes","Tier 0: Emergency",IF(AG7>=100,"Tier 1: Fast Track",IF(AG7>=50,"Tier 2: Standard Delivery",IF(AG7>=10,"Tier 3: Custom Engagement","Tier 4: Backlog")))) -> Tier 4: Backlog | AI7: =IF(T7="Yes","Negative (Risk of Loss)",IF(L7="Retention/Risk of Loss","Negative (Risk of Loss)",IF(AND(K7>0,OR(L7="New Contract",L7="Expansion")),"Positive (New Revenue)","Neutral (Internal/Platform)"))) -> Neutral (Internal/Platform) | AJ7: =IF(NOT(ISBLANK(K7)),K7*(O7/100),0) -> 0 | AP7: =COUNTIF(Master_Data_JIRA_Tickets!I:I,B7) -> 0 | AS7: No | AT7: Not Started | AU7: No
B8: F-006 | C8: Simplified Agentic UI Design | D8: Platform (All Agents) | E8: Platform Improvements | F8: Q4 2025 | G8: 5 | H8: Multiple | I8: 0 | J8: Platform Enhancement | X8: =IF(H8="Multiple",IF(ISBLANK(I8),1,LEN(I8)-LEN(SUBSTITUTE(I8,",",""))+1),IF(NOT(ISBLANK(I8)),LEN(I8)-LEN(SUBSTITUTE(I8,",",""))+2,1)) -> 1 | Z8: =IF(NOT(ISBLANK(Y8)),Y8-TODAY(),"") | AG8: =IF(AND(NOT(ISBLANK(K8)),NOT(ISBLANK(G8)),NOT(ISBLANK(O8)),NOT(ISBLANK(AB8)),AB8>0),(K8*G8*(O8/100))/AB8,0) -> 0 | AH8: =IF(T8="Yes","Tier 0: Emergency",IF(AG8>=100,"Tier 1: Fast Track",IF(AG8>=50,"Tier 2: Standard Delivery",IF(AG8>=10,"Tier 3: Custom Engagement","Tier 4: Backlog")))) -> Tier 4: Backlog | AI8: =IF(T8="Yes","Negative (Risk of Loss)",IF(L8="Retention/Risk of Loss","Negative (Risk of Loss)",IF(AND(K8>0,OR(L8="New Contract",L8="Expansion")),"Positive (New Revenue)","Neutral (Internal/Platform)"))) -> Neutral (Internal/Platform) | AJ8: =IF(NOT(ISBLANK(K8)),K8*(O8/100),0) -> 0 | AP8: =COUNTIF(Master_Data_JIRA_Tickets!I:I,B8) -> 0 | AS8: Yes | AT8: In Progress | AU8: Yes
B9: F-007 | C9: Matching Engine UI | D9: Matching Engine | E9: Platform Improvements | F9: Q4 2025 | G9: 4 | H9: Multiple | I9: 0 | J9: Platform Enhancement | X9: =IF(H9="Multiple",IF(ISBLANK(I9),1,LEN(I9)-LEN(SUBSTITUTE(I9,",",""))+1),IF(NOT(ISBLANK(I9)),LEN(I9)-LEN(SUBSTITUTE(I9,",",""))+2,1)) -> 1 | Z9: =IF(NOT(ISBLANK(Y9)),Y9-TODAY(),"") | AG9: =IF(AND(NOT(ISBLANK(K9)),NOT(ISBLANK(G9)),NOT(ISBLANK(O9)),NOT(ISBLANK(AB9)),AB9>0),(K9*G9*(O9/100))/AB9,0) -> 0 | AH9: =IF(T9="Yes","Tier 0: Emergency",IF(AG9>=100,"Tier 1: Fast Track",IF(AG9>=50,"Tier 2: Standard Delivery",IF(AG9>=10,"Tier 3: Custom Engagement","Tier 4: Backlog")))) -> Tier 4: Backlog | AI9: =IF(T9="Yes","Negative (Risk of Loss)",IF(L9="Retention/Risk of Loss","Negative (Risk of Loss)",IF(AND(K9>0,OR(L9="New Contract",L9="Expansion")),"Positive (New Revenue)","Neutral (Internal/Platform)"))) -> Neutral (Internal/Platform) | AJ9: =IF(NOT(ISBLANK(K9)),K9*(O9/100),0) -> 0 | AP9: =COUNTIF(Master_Data_JIRA_Tickets!I:I,B9) -> 0 | AS9: No | AT9: Not Started | AU9: No
B10: F-008 | C10: Information Graph Enhanced Infrastructure | D10: Platform (All Agents) | E10: Core Infrastructure | F10: Q1 2026 | G10: 5 | H10: Multiple | I10: 0 | J10: Platform Enhancement | X10: =IF(H10="Multiple",IF(ISBLANK(I10),1,LEN(I10)-LEN(SUBSTITUTE(I10,",",""))+1),IF(NOT(ISBLANK(I10)),LEN(I10)-LEN(SUBSTITUTE(I10,",",""))+2,1)) -> 1 | Z10: =IF(NOT(ISBLANK(Y10)),Y10-TODAY(),"") | AG10: =IF(AND(NOT(ISBLANK(K10)),NOT(ISBLANK(G10)),NOT(ISBLANK(O10)),NOT(ISBLANK(AB10)),AB10>0),(K10*G10*(O10/100))/AB10,0) -> 0 | AH10: =IF(T10="Yes","Tier 0: Emergency",IF(AG10>=100,"Tier 1: Fast Track",IF(AG10>=50,"Tier 2: Standard Delivery",IF(AG10>=10,"Tier 3: Custom Engagement","Tier 4: Backlog")))) -> Tier 4: Backlog | AI10: =IF(T10="Yes","Negative (Risk of Loss)",IF(L10="Retention/Risk of Loss","Negative (Risk of Loss)",IF(AND(K10>0,OR(L10="New Contract",L10="Expansion")),"Positive (New Revenue)","Neutral (Internal/Platform)"))) -> Neutral (Internal/Platform) | AJ10: =IF(NOT(ISBLANK(K10)),K10*(O10/100),0) -> 0 | AP10: =COUNTIF(Master_Data_JIRA_Tickets!I:I,B10) -> 0 | AS10: Yes | AT10: In Progress | AU10: Yes
B11: F-009 | C11: Enhanced Agent Outcome Reasoning and Planning | D11: Platform (All Agents) | E11: Platform Improvements | F11: Q1 2026 | G11: 5 | H11: Multiple | I11: 0 | J11: Platform Enhancement | X11: =IF(H11="Multiple",IF(ISBLANK(I11),1,LEN(I11)-LEN(SUBSTITUTE(I11,",",""))+1),IF(NOT(ISBLANK(I11)),LEN(I11)-LEN(SUBSTITUTE(I11,",",""))+2,1)) -> 1 | Z11: =IF(NOT(ISBLANK(Y11)),Y11-TODAY(),"") | AG11: =IF(AND(NOT(ISBLANK(K11)),NOT(ISBLANK(G11)),NOT(ISBLANK(O11)),NOT(ISBLANK(AB11)),AB11>0),(K11*G11*(O11/100))/AB11,0) -> 0 | AH11: =IF(T11="Yes","Tier 0: Emergency",IF(AG11>=100,"Tier 1: Fast Track",IF(AG11>=50,"Tier 2: Standard Delivery",IF(AG11>=10,"Tier 3: Custom Engagement","Tier 4: Backlog")))) -> Tier 4: Backlog | AI11: =IF(T11="Yes","Negative (Risk of Loss)",IF(L11="Retention/Risk of Loss","Negative (Risk of Loss)",IF(AND(K11>0,OR(L11="New Contract",L11="Expansion")),"Positive (New Revenue)","Neutral (Internal/Platform)"))) -> Neutral (Internal/Platform) | AJ11: =IF(NOT(ISBLANK(K11)),K11*(O11/100),0) -> 0 | AP11: =COUNTIF(Master_Data_JIRA_Tickets!I:I,B11) -> 0 | AS11: Yes | AT11: In Progress | AU11: Yes
B12: F-010 | C12: Inference / Training speed improvements | D12: Platform (All Agents) | E12: Core Infrastructure | F12: Q1 2026 | G12: 5 | H12: Multiple | I12: 0 | J12: Platform Enhancement | X12: =IF(H12="Multiple",IF(ISBLANK(I12),1,LEN(I12)-LEN(SUBSTITUTE(I12,",",""))+1),IF(NOT(ISBLANK(I12)),LEN(I12)-LEN(SUBSTITUTE(I12,",",""))+2,1)) -> 1 | Z12: =IF(NOT(ISBLANK(Y12)),Y12-TODAY(),"") | AG12: =IF(AND(NOT(ISBLANK(K12)),NOT(ISBLANK(G12)),NOT(ISBLANK(O12)),NOT(ISBLANK(AB12)),AB12>0),(K12*G12*(O12/100))/AB12,0) -> 0 | AH12: =IF(T12="Yes","Tier 0: Emergency",IF(AG12>=100,"Tier 1: Fast Track",IF(AG12>=50,"Tier 2: Standard Delivery",IF(AG12>=10,"Tier 3: Custom Engagement","Tier 4: Backlog")))) -> Tier 4: Backlog | AI12: =IF(T12="Yes","Negative (Risk of Loss)",IF(L12="Retention/Risk of Loss","Negative (Risk of Loss)",IF(AND(K12>0,OR(L12="New Contract",L12="Expansion")),"Positive (New Revenue)","Neutral (Internal/Platform)"))) -> Neutral (Internal/Platform) | AJ12: =IF(NOT(ISBLANK(K12)),K12*(O12/100),0) -> 0 | AP12: =COUNTIF(Master_Data_JIRA_Tickets!I:I,B12) -> 0 | AS12: Yes | AT12: In Progress | AU12: Yes
B13: F-011 | C13: Activity Tracing Across Agents | D13: Platform (Analytics) | E13: Platform Improvements | F13: Q1 2026 | G13: 5 | H13: Multiple | I13: 0 | J13: Platform Enhancement | X13: =IF(H13="Multiple",IF(ISBLANK(I13),1,LEN(I13)-LEN(SUBSTITUTE(I13,",",""))+1),IF(NOT(ISBLANK(I13)),LEN(I13)-LEN(SUBSTITUTE(I13,",",""))+2,1)) -> 1 | Z13: =IF(NOT(ISBLANK(Y13)),Y13-TODAY(),"") | AG13: =IF(AND(NOT(ISBLANK(K13)),NOT(ISBLANK(G13)),NOT(ISBLANK(O13)),NOT(ISBLANK(AB13)),AB13>0),(K13*G13*(O13/100))/AB13,0) -> 0 | AH13: =IF(T13="Yes","Tier 0: Emergency",IF(AG13>=100,"Tier 1: Fast Track",IF(AG13>=50,"Tier 2: Standard Delivery",IF(AG13>=10,"Tier 3: Custom Engagement","Tier 4: Backlog")))) -> Tier 4: Backlog | AI13: =IF(T13="Yes","Negative (Risk of Loss)",IF(L13="Retention/Risk of Loss","Negative (Risk of Loss)",IF(AND(K13>0,OR(L13="New Contract",L13="Expansion")),"Positive (New Revenue)","Neutral (Internal/Platform)"))) -> Neutral (Internal/Platform) | AJ13: =IF(NOT(ISBLANK(K13)),K13*(O13/100),0) -> 0 | AP13: =COUNTIF(Master_Data_JIRA_Tickets!I:I,B13) -> 0 | AS13: No | AT13: Not Started | AU13: No
B14: F-012 | C14: Exception Prediction | D14: Platform (Analytics) | E14: Platform Improvements | F14: Q1 2026 | G14: 5 | H14: Multiple | I14: 0 | J14: Platform Enhancement | X14: =IF(H14="Multiple",IF(ISBLANK(I14),1,LEN(I14)-LEN(SUBSTITUTE(I14,",",""))+1),IF(NOT(ISBLANK(I14)),LEN(I14)-LEN(SUBSTITUTE(I14,",",""))+2,1)) -> 1 | Z14: =IF(NOT(ISBLANK(Y14)),Y14-TODAY(),"") | AG14: =IF(AND(NOT(ISBLANK(K14)),NOT(ISBLANK(G14)),NOT(ISBLANK(O14)),NOT(ISBLANK(AB14)),AB14>0),(K14*G14*(O14/100))/AB14,0) -> 0 | AH14: =IF(T14="Yes","Tier 0: Emergency",IF(AG14>=100,"Tier 1: Fast Track",IF(AG14>=50,"Tier 2: Standard Delivery",IF(AG14>=10,"Tier 3: Custom Engagement","Tier 4: Backlog")))) -> Tier 4: Backlog | AI14: =IF(T14="Yes","Negative (Risk of Loss)",IF(L14="Retention/Risk of Loss","Negative (Risk of Loss)",IF(AND(K14>0,OR(L14="New Contract",L14="Expansion")),"Positive (New Revenue)","Neutral (Internal/Platform)"))) -> Neutral (Internal/Platform) | AJ14: =IF(NOT(ISBLANK(K14)),K14*(O14/100),0) -> 0 | AP14: =COUNTIF(Master_Data_JIRA_Tickets!I:I,B14) -> 0 | AS14: No | AT14: Not Started | AU14: No
... B27: F-025 | C27: Enhanced Testing Suite UI Implementation | D27: Platform (All Agents) | E27: Platform Improvements | F27: Q3 2026 | G27: 5 | H27: Multiple | I27: 0 | J27: Platform Enhancement | X27: =IF(H27="Multiple",IF(ISBLANK(I27),1,LEN(I27)-LEN(SUBSTITUTE(I27,",",""))+1),IF(NOT(ISBLANK(I27)),LEN(I27)-LEN(SUBSTITUTE(I27,",",""))+2,1)) -> 1 | Z27: =IF(NOT(ISBLANK(Y27)),Y27-TODAY(),"") | AG27: =IF(AND(NOT(ISBLANK(K27)),NOT(ISBLANK(G27)),NOT(ISBLANK(O27)),NOT(ISBLANK(AB27)),AB27>0),(K27*G27*(O27/100))/AB27,0) -> 0 | AH27: =IF(T27="Yes","Tier 0: Emergency",IF(AG27>=100,"Tier 1: Fast Track",IF(AG27>=50,"Tier 2: Standard Delivery",IF(AG27>=10,"Tier 3: Custom Engagement","Tier 4: Backlog")))) -> Tier 4: Backlog | AI27: =IF(T27="Yes","Negative (Risk of Loss)",IF(L27="Retention/Risk of Loss","Negative (Risk of Loss)",IF(AND(K27>0,OR(L27="New Contract",L27="Expansion")),"Positive (New Revenue)","Neutral (Internal/Platform)"))) -> Neutral (Internal/Platform) | AJ27: =IF(NOT(ISBLANK(K27)),K27*(O27/100),0) -> 0 | AP27: =COUNTIF(Master_Data_JIRA_Tickets!I:I,B27) -> 0 | AS27: No | AT27: Not Started | AU27: No
B28: F-026 | C28: DTCC Agent Onboarding - Trade Processing Phase 1 | D28: Trade Processing | E28: Client-Specific Work | F28: Q4 2025 | G28: 3 | H28: DTCC | I28: 0 | J28: Client-Specific | K28: 750000 | L28: New Contract | M28: Signed | N28: Closed Won | O28: 1 | Q28: 0.6 | R28: 2025-12-31 | S28: 0 | T28: 0 | U28: 0 | V28: Daily client meetings, high touch | W28: 0 | X28: =IF(H28="Multiple",IF(ISBLANK(I28),1,LEN(I28)-LEN(SUBSTITUTE(I28,",",""))+1),IF(NOT(ISBLANK(I28)),LEN(I28)-LEN(SUBSTITUTE(I28,",",""))+2,1)) -> 2 | Z28: =IF(NOT(ISBLANK(Y28)),Y28-TODAY(),"") | AB28: 12 | AC28: L-Large 8wks | AD28: High | AE28: Service fabric deployment, security audit | AF28: Multiple Teams | AG28: =IF(AND(NOT(ISBLANK(K28)),NOT(ISBLANK(G28)),NOT(ISBLANK(O28)),NOT(ISBLANK(AB28)),AB28>0),(K28*G28*(O28/100))/AB28,0) -> 1875 | AH28: =IF(T28="Yes","Tier 0: Emergency",IF(AG28>=100,"Tier 1: Fast Track",IF(AG28>=50,"Tier 2: Standard Delivery",IF(AG28>=10,"Tier 3: Custom Engagement","Tier 4: Backlog")))) -> Tier 1: Fast Track | AI28: =IF(T28="Yes","Negative (Risk of Loss)",IF(L28="Retention/Risk of Loss","Negative (Risk of Loss)",IF(AND(K28>0,OR(L28="New Contract",L28="Expansion")),"Positive (New Revenue)","Neutral (Internal/Platform)"))) -> Positive (New Revenue) | AJ28: =IF(NOT(ISBLANK(K28)),K28*(O28/100),0) -> 7500 | AP28: =COUNTIF(Master_Data_JIRA_Tickets!I:I,B28) -> 0 | AS28: No | AT28: Complete | AU28: Yes
B29: F-027 | C29: DTCC Agent Onboarding - Trade Processing Phase 2 | D29: Trade Processing | E29: Client-Specific Work | F29: Q1 2026 | G29: 3 | H29: DTCC | I29: 0 | J29: Client-Specific | X29: =IF(H29="Multiple",IF(ISBLANK(I29),1,LEN(I29)-LEN(SUBSTITUTE(I29,",",""))+1),IF(NOT(ISBLANK(I29)),LEN(I29)-LEN(SUBSTITUTE(I29,",",""))+2,1)) -> 2 | Z29: =IF(NOT(ISBLANK(Y29)),Y29-TODAY(),"") | AG29: =IF(AND(NOT(ISBLANK(K29)),NOT(ISBLANK(G29)),NOT(ISBLANK(O29)),NOT(ISBLANK(AB29)),AB29>0),(K29*G29*(O29/100))/AB29,0) -> 0 | AH29: =IF(T29="Yes","Tier 0: Emergency",IF(AG29>=100,"Tier 1: Fast Track",IF(AG29>=50,"Tier 2: Standard Delivery",IF(AG29>=10,"Tier 3: Custom Engagement","Tier 4: Backlog")))) -> Tier 4: Backlog | AI29: =IF(T29="Yes","Negative (Risk of Loss)",IF(L29="Retention/Risk of Loss","Negative (Risk of Loss)",IF(AND(K29>0,OR(L29="New Contract",L29="Expansion")),"Positive (New Revenue)","Neutral (Internal/Platform)"))) -> Neutral (Internal/Platform) | AJ29: =IF(NOT(ISBLANK(K29)),K29*(O29/100),0) -> 0 | AP29: =COUNTIF(Master_Data_JIRA_Tickets!I:I,B29) -> 0 | AS29: No | AT29: Not Started | AU29: No
B30: F-028 | C30: DTCC Agent Onboarding - Core Reconciliation | D30: Core Reconciliation | E30: Client-Specific Work | F30: Q1 2026 | G30: 3 | H30: DTCC | I30: 0 | J30: Client-Specific | X30: =IF(H30="Multiple",IF(ISBLANK(I30),1,LEN(I30)-LEN(SUBSTITUTE(I30,",",""))+1),IF(NOT(ISBLANK(I30)),LEN(I30)-LEN(SUBSTITUTE(I30,",",""))+2,1)) -> 2 | Z30: =IF(NOT(ISBLANK(Y30)),Y30-TODAY(),"") | AG30: =IF(AND(NOT(ISBLANK(K30)),NOT(ISBLANK(G30)),NOT(ISBLANK(O30)),NOT(ISBLANK(AB30)),AB30>0),(K30*G30*(O30/100))/AB30,0) -> 0 | AH30: =IF(T30="Yes","Tier 0: Emergency",IF(AG30>=100,"Tier 1: Fast Track",IF(AG30>=50,"Tier 2: Standard Delivery",IF(AG30>=10,"Tier 3: Custom Engagement","Tier 4: Backlog")))) -> Tier 4: Backlog | AI30: =IF(T30="Yes","Negative (Risk of Loss)",IF(L30="Retention/Risk of Loss","Negative (Risk of Loss)",IF(AND(K30>0,OR(L30="New Contract",L30="Expansion")),"Positive (New Revenue)","Neutral (Internal/Platform)"))) -> Neutral (Internal/Platform) | AJ30: =IF(NOT(ISBLANK(K30)),K30*(O30/100),0) -> 0 | AP30: =COUNTIF(Master_Data_JIRA_Tickets!I:I,B30) -> 0 | AS30: No | AT30: Not Started | AU30: No
B31: F-029 | C31: Broadridge Trade Matching Engine Enhancement | D31: Matching Engine | E31: Client-Specific Work | F31: Q4 2025 | G31: 2 | H31: Broadridge | J31: Client-Specific | X31: =IF(H31="Multiple",IF(ISBLANK(I31),1,LEN(I31)-LEN(SUBSTITUTE(I31,",",""))+1),IF(NOT(ISBLANK(I31)),LEN(I31)-LEN(SUBSTITUTE(I31,",",""))+2,1)) -> 1 | Z31: =IF(NOT(ISBLANK(Y31)),Y31-TODAY(),"") | AG31: =IF(AND(NOT(ISBLANK(K31)),NOT(ISBLANK(G31)),NOT(ISBLANK(O31)),NOT(ISBLANK(AB31)),AB31>0),(K31*G31*(O31/100))/AB31,0) -> 0 | AH31: =IF(T31="Yes","Tier 0: Emergency",IF(AG31>=100,"Tier 1: Fast Track",IF(AG31>=50,"Tier 2: Standard Delivery",IF(AG31>=10,"Tier 3: Custom Engagement","Tier 4: Backlog")))) -> Tier 4: Backlog | AI31: =IF(T31="Yes","Negative (Risk of Loss)",IF(L31="Retention/Risk of Loss","Negative (Risk of Loss)",IF(AND(K31>0,OR(L31="New Contract",L31="Expansion")),"Positive (New Revenue)","Neutral (Internal/Platform)"))) -> Neutral (Internal/Platform) | AJ31: =IF(NOT(ISBLANK(K31)),K31*(O31/100),0) -> 0 | AP31: =COUNTIF(Master_Data_JIRA_Tickets!I:I,B31) -> 0 | AS31: No | AT31: Not Started | AU31: No
B32: F-030 | C32: Broadridge Email Automation Workflow | D32: Email Automation | E32: Client-Specific Work | F32: Q4 2025 | G32: 3 | H32: Broadridge | J32: Client-Specific | K32: 500000 | L32: Expansion | M32: Signed | N32: Closed Won | O32: 1 | X32: =IF(H32="Multiple",IF(ISBLANK(I32),1,LEN(I32)-LEN(SUBSTITUTE(I32,",",""))+1),IF(NOT(ISBLANK(I32)),LEN(I32)-LEN(SUBSTITUTE(I32,",",""))+2,1)) -> 1 | Z32: =IF(NOT(ISBLANK(Y32)),Y32-TODAY(),"") | AB32: 8 | AC32: L-Large 8wks | AD32: Medium | AF32: Backend | AG32: =IF(AND(NOT(ISBLANK(K32)),NOT(ISBLANK(G32)),NOT(ISBLANK(O32)),NOT(ISBLANK(AB32)),AB32>0),(K32*G32*(O32/100))/AB32,0) -> 1875 | AH32: =IF(T32="Yes","Tier 0: Emergency",IF(AG32>=100,"Tier 1: Fast Track",IF(AG32>=50,"Tier 2: Standard Delivery",IF(AG32>=10,"Tier 3: Custom Engagement","Tier 4: Backlog")))) -> Tier 1: Fast Track | AI32: =IF(T32="Yes","Negative (Risk of Loss)",IF(L32="Retention/Risk of Loss","Negative (Risk of Loss)",IF(AND(K32>0,OR(L32="New Contract",L32="Expansion")),"Positive (New Revenue)","Neutral (Internal/Platform)"))) -> Positive (New Revenue) | AJ32: =IF(NOT(ISBLANK(K32)),K32*(O32/100),0) -> 5000 | AP32: =COUNTIF(Master_Data_JIRA_Tickets!I:I,B32) -> 0 | AS32: No | AT32: Complete | AU32: Yes
B33: F-031 | C33: Broadridge Critical Bug Fix - Trade Processing | D33: Trade Processing | E33: Bug Fixes | F33: Q4 2025 | G33: 1 | H33: Broadridge | J33: Client-Specific | K33: -500000 | L33: Retention/Risk of Loss | M33: 0 | N33: 0 | O33: 1 | P33: In Progress | Q33: 0.7 | S33: 1 | T33: Yes | U33: -500000 | V33: Tier 0: Emergency | X33: =IF(H33="Multiple",IF(ISBLANK(I33),1,LEN(I33)-LEN(SUBSTITUTE(I33,",",""))+1),IF(NOT(ISBLANK(I33)),LEN(I33)-LEN(SUBSTITUTE(I33,",",""))+2,1)) -> 1 | Z33: =IF(NOT(ISBLANK(Y33)),Y33-TODAY(),"") | AB33: 1 | AC33: S-Small 2wks | AD33: Low | AF33: Backend | AG33: =IF(AND(NOT(ISBLANK(K33)),NOT(ISBLANK(G33)),NOT(ISBLANK(O33)),NOT(ISBLANK(AB33)),AB33>0),(K33*G33*(O33/100))/AB33,0) -> -5000 | AH33: =IF(T33="Yes","Tier 0: Emergency",IF(AG33>=100,"Tier 1: Fast Track",IF(AG33>=50,"Tier 2: Standard Delivery",IF(AG33>=10,"Tier 3: Custom Engagement","Tier 4: Backlog")))) -> Tier 0: Emergency | AI33: =IF(T33="Yes","Negative (Risk of Loss)",IF(L33="Retention/Risk of Loss","Negative (Risk of Loss)",IF(AND(K33>0,OR(L33="New Contract",L33="Expansion")),"Positive (New Revenue)","Neutral (Internal/Platform)"))) -> Negative (Risk of Loss) | AJ33: =IF(NOT(ISBLANK(K33)),K33*(O33/100),0) -> -5000 | AP33: =COUNTIF(Master_Data_JIRA_Tickets!I:I,B33) -> 0 | AS33: No | AT33: Complete | AU33: Yes
B34: F-032 | C34: JP Morgan Monthly Reconciliation Enhancement | D34: Core Reconciliation | E34: Client-Specific Work | F34: Q1 2026 | G34: 3 | H34: JP Morgan | J34: Client-Specific | X34: =IF(H34="Multiple",IF(ISBLANK(I34),1,LEN(I34)-LEN(SUBSTITUTE(I34,",",""))+1),IF(NOT(ISBLANK(I34)),LEN(I34)-LEN(SUBSTITUTE(I34,",",""))+2,1)) -> 1 | Z34: =IF(NOT(ISBLANK(Y34)),Y34-TODAY(),"") | AG34: =IF(AND(NOT(ISBLANK(K34)),NOT(ISBLANK(G34)),NOT(ISBLANK(O34)),NOT(ISBLANK(AB34)),AB34>0),(K34*G34*(O34/100))/AB34,0) -> 0 | AH34: =IF(T34="Yes","Tier 0: Emergency",IF(AG34>=100,"Tier 1: Fast Track",IF(AG34>=50,"Tier 2: Standard Delivery",IF(AG34>=10,"Tier 3: Custom Engagement","Tier 4: Backlog")))) -> Tier 4: Backlog | AI34: =IF(T34="Yes","Negative (Risk of Loss)",IF(L34="Retention/Risk of Loss","Negative (Risk of Loss)",IF(AND(K34>0,OR(L34="New Contract",L34="Expansion")),"Positive (New Revenue)","Neutral (Internal/Platform)"))) -> Neutral (Internal/Platform) | AJ34: =IF(NOT(ISBLANK(K34)),K34*(O34/100),0) -> 0 | AP34: =COUNTIF(Master_Data_JIRA_Tickets!I:I,B34) -> 0 | AS34: No | AT34: Not Started | AU34: No
B35: F-033 | C35: JP Morgan Security Settlements Optimization | D35: Security Settlements | E35: Client-Specific Work | F35: Q2 2026 | G35: 3 | H35: JP Morgan | J35: Client-Specific | X35: =IF(H35="Multiple",IF(ISBLANK(I35),1,LEN(I35)-LEN(SUBSTITUTE(I35,",",""))+1),IF(NOT(ISBLANK(I35)),LEN(I35)-LEN(SUBSTITUTE(I35,",",""))+2,1)) -> 1 | Z35: =IF(NOT(ISBLANK(Y35)),Y35-TODAY(),"") | AG35: =IF(AND(NOT(ISBLANK(K35)),NOT(ISBLANK(G35)),NOT(ISBLANK(O35)),NOT(ISBLANK(AB35)),AB35>0),(K35*G35*(O35/100))/AB35,0) -> 0 | AH35: =IF(T35="Yes","Tier 0: Emergency",IF(AG35>=100,"Tier 1: Fast Track",IF(AG35>=50,"Tier 2: Standard Delivery",IF(AG35>=10,"Tier 3: Custom Engagement","Tier 4: Backlog")))) -> Tier 4: Backlog | AI35: =IF(T35="Yes","Negative (Risk of Loss)",IF(L35="Retention/Risk of Loss","Negative (Risk of Loss)",IF(AND(K35>0,OR(L35="New Contract",L35="Expansion")),"Positive (New Revenue)","Neutral (Internal/Platform)"))) -> Neutral (Internal/Platform) | AJ35: =IF(NOT(ISBLANK(K35)),K35*(O35/100),0) -> 0 | AP35: =COUNTIF(Master_Data_JIRA_Tickets!I:I,B35) -> 0 | AS35: No | AT35: Not Started | AU35: No
B36: F-034 | C36: Accenture Email Automation Deployment | D36: Email Automation | E36: Client-Specific Work | F36: Q4 2025 | G36: 4 | H36: Accenture | J36: Client-Specific | K36: 1200000 | L36: New Contract | M36: Signed | N36: Closed Won | O36: 1 | X36: =IF(H36="Multiple",IF(ISBLANK(I36),1,LEN(I36)-LEN(SUBSTITUTE(I36,",",""))+1),IF(NOT(ISBLANK(I36)),LEN(I36)-LEN(SUBSTITUTE(I36,",",""))+2,1)) -> 1 | Z36: =IF(NOT(ISBLANK(Y36)),Y36-TODAY(),"") | AB36: 8 | AC36: L-Large 8wks | AD36: Medium | AF36: Multiple Teams | AG36: =IF(AND(NOT(ISBLANK(K36)),NOT(ISBLANK(G36)),NOT(ISBLANK(O36)),NOT(ISBLANK(AB36)),AB36>0),(K36*G36*(O36/100))/AB36,0) -> 6000 | AH36: =IF(T36="Yes","Tier 0: Emergency",IF(AG36>=100,"Tier 1: Fast Track",IF(AG36>=50,"Tier 2: Standard Delivery",IF(AG36>=10,"Tier 3: Custom Engagement","Tier 4: Backlog")))) -> Tier 1: Fast Track | AI36: =IF(T36="Yes","Negative (Risk of Loss)",IF(L36="Retention/Risk of Loss","Negative (Risk of Loss)",IF(AND(K36>0,OR(L36="New Contract",L36="Expansion")),"Positive (New Revenue)","Neutral (Internal/Platform)"))) -> Positive (New Revenue) | AJ36: =IF(NOT(ISBLANK(K36)),K36*(O36/100),0) -> 12000 | AP36: =COUNTIF(Master_Data_JIRA_Tickets!I:I,B36) -> 0 | AS36: No | AT36: Complete | AU36: Yes
B37: F-035 | C37: Accenture Multi-Agent Orchestration | D37: Platform (All Agents) | E37: Client-Specific Work | F37: Q1 2026 | G37: 4 | H37: Accenture | J37: Both | X37: =IF(H37="Multiple",IF(ISBLANK(I37),1,LEN(I37)-LEN(SUBSTITUTE(I37,",",""))+1),IF(NOT(ISBLANK(I37)),LEN(I37)-LEN(SUBSTITUTE(I37,",",""))+2,1)) -> 1 | Z37: =IF(NOT(ISBLANK(Y37)),Y37-TODAY(),"") | AG37: =IF(AND(NOT(ISBLANK(K37)),NOT(ISBLANK(G37)),NOT(ISBLANK(O37)),NOT(ISBLANK(AB37)),AB37>0),(K37*G37*(O37/100))/AB37,0) -> 0 | AH37: =IF(T37="Yes","Tier 0: Emergency",IF(AG37>=100,"Tier 1: Fast Track",IF(AG37>=50,"Tier 2: Standard Delivery",IF(AG37>=10,"Tier 3: Custom Engagement","Tier 4: Backlog")))) -> Tier 4: Backlog | AI37: =IF(T37="Yes","Negative (Risk of Loss)",IF(L37="Retention/Risk of Loss","Negative (Risk of Loss)",IF(AND(K37>0,OR(L37="New Contract",L37="Expansion")),"Positive (New Revenue)","Neutral (Internal/Platform)"))) -> Neutral (Internal/Platform) | AJ37: =IF(NOT(ISBLANK(K37)),K37*(O37/100),0) -> 0 | AP37: =COUNTIF(Master_Data_JIRA_Tickets!I:I,B37) -> 0 | AS37: No | AT37: Not Started | AU37: No
B38: F-036 | C38: SSI Agent Deployment - Colony Bank | D38: Standing Settlement Instructions | E38: Client-Specific Work | F38: Q4 2025 | G38: 5 | H38: Regional Banks | I38: Colony Bank | J38: Platform Enhancement | K38: 200000 | L38: New Contract | M38: Signed | N38: Closed Won | O38: 1 | P38: In Progress | Q38: 0.4 | R38: 2025-12-15 | S38: 6 | X38: =IF(H38="Multiple",IF(ISBLANK(I38),1,LEN(I38)-LEN(SUBSTITUTE(I38,",",""))+1),IF(NOT(ISBLANK(I38)),LEN(I38)-LEN(SUBSTITUTE(I38,",",""))+2,1)) -> 2 | Z38: =IF(NOT(ISBLANK(Y38)),Y38-TODAY(),"") | AB38: 6 | AC38: M-Medium 4wks | AD38: Medium | AF38: Backend | AG38: =IF(AND(NOT(ISBLANK(K38)),NOT(ISBLANK(G38)),NOT(ISBLANK(O38)),NOT(ISBLANK(AB38)),AB38>0),(K38*G38*(O38/100))/AB38,0) -> 1666.6667 | AH38: =IF(T38="Yes","Tier 0: Emergency",IF(AG38>=100,"Tier 1: Fast Track",IF(AG38>=50,"Tier 2: Standard Delivery",IF(AG38>=10,"Tier 3: Custom Engagement","Tier 4: Backlog")))) -> Tier 1: Fast Track | AI38: =IF(T38="Yes","Negative (Risk of Loss)",IF(L38="Retention/Risk of Loss","Negative (Risk of Loss)",IF(AND(K38>0,OR(L38="New Contract",L38="Expansion")),"Positive (New Revenue)","Neutral (Internal/Platform)"))) -> Positive (New Revenue) | AJ38: =IF(NOT(ISBLANK(K38)),K38*(O38/100),0) -> 2000 | AP38: =COUNTIF(Master_Data_JIRA_Tickets!I:I,B38) -> 0 | AS38: No | AT38: Complete | AU38: Yes
B39: F-037 | C39: SSI Agent Deployment - Sunwest Bank | D39: Standing Settlement Instructions | E39: Client-Specific Work | F39: Q1 2026 | G39: 5 | H39: Regional Banks | I39: Sunwest Bank | J39: Platform Enhancement | K39: 180000 | L39: New Contract | M39: Contract Negotiation | N39: Contract Negotiation | O39: 0.8 | X39: =IF(H39="Multiple",IF(ISBLANK(I39),1,LEN(I39)-LEN(SUBSTITUTE(I39,",",""))+1),IF(NOT(ISBLANK(I39)),LEN(I39)-LEN(SUBSTITUTE(I39,",",""))+2,1)) -> 2 | Z39: =IF(NOT(ISBLANK(Y39)),Y39-TODAY(),"") | AB39: 6 | AC39: M-Medium 4wks | AD39: Medium | AF39: Backend | AG39: =IF(AND(NOT(ISBLANK(K39)),NOT(ISBLANK(G39)),NOT(ISBLANK(O39)),NOT(ISBLANK(AB39)),AB39>0),(K39*G39*(O39/100))/AB39,0) -> 1200 | AH39: =IF(T39="Yes","Tier 0: Emergency",IF(AG39>=100,"Tier 1: Fast Track",IF(AG39>=50,"Tier 2: Standard Delivery",IF(AG39>=10,"Tier 3: Custom Engagement","Tier 4: Backlog")))) -> Tier 1: Fast Track | AI39: =IF(T39="Yes","Negative (Risk of Loss)",IF(L39="Retention/Risk of Loss","Negative (Risk of Loss)",IF(AND(K39>0,OR(L39="New Contract",L39="Expansion")),"Positive (New Revenue)","Neutral (Internal/Platform)"))) -> Positive (New Revenue) | AJ39: =IF(NOT(ISBLANK(K39)),K39*(O39/100),0) -> 1440 | AP39: =COUNTIF(Master_Data_JIRA_Tickets!I:I,B39) -> 0 | AS39: No | AT39: Complete | AU39: Yes
B40: F-038 | C40: Vantage Bank Custom Reconciliation (POC) | D40: Core Reconciliation | E40: Client-Specific Work | F40: Q1 2026 | G40: 2 | H40: Regional Banks | I40: Vantage Bank | J40: Client-Specific | K40: 200000 | L40: New Contract | M40: POC | N40: POC | O40: 0.5 | P40: Not Started | S40: 12 | W40: Only proceed if Vantage prepays 50% or signs binding contract | X40: =IF(H40="Multiple",IF(ISBLANK(I40),1,LEN(I40)-LEN(SUBSTITUTE(I40,",",""))+1),IF(NOT(ISBLANK(I40)),LEN(I40)-LEN(SUBSTITUTE(I40,",",""))+2,1)) -> 2 | Z40: =IF(NOT(ISBLANK(Y40)),Y40-TODAY(),"") | AB40: 12 | AC40: XL-Extra Large 12wks+ | AD40: High | AE40: Client requires prepayment | AF40: Backend | AG40: =IF(AND(NOT(ISBLANK(K40)),NOT(ISBLANK(G40)),NOT(ISBLANK(O40)),NOT(ISBLANK(AB40)),AB40>0),(K40*G40*(O40/100))/AB40,0) -> 166.66667 | AH40: =IF(T40="Yes","Tier 0: Emergency",IF(AG40>=100,"Tier 1: Fast Track",IF(AG40>=50,"Tier 2: Standard Delivery",IF(AG40>=10,"Tier 3: Custom Engagement","Tier 4: Backlog")))) -> Tier 1: Fast Track | AI40: =IF(T40="Yes","Negative (Risk of Loss)",IF(L40="Retention/Risk of Loss","Negative (Risk of Loss)",IF(AND(K40>0,OR(L40="New Contract",L40="Expansion")),"Positive (New Revenue)","Neutral (Internal/Platform)"))) -> Positive (New Revenue) | AJ40: =IF(NOT(ISBLANK(K40)),K40*(O40/100),0) -> 1000 | AP40: =COUNTIF(Master_Data_JIRA_Tickets!I:I,B40) -> 0 | AS40: No | AT40: Complete | AU40: Yes
B41: F-039 | C41: Email Automation - Response Generation Enhancement | D41: Email Automation | E41: Platform Improvements | F41: Q2 2026 | G41: 5 | H41: Multiple | I41: 0 | J41: Platform Enhancement | X41: =IF(H41="Multiple",IF(ISBLANK(I41),1,LEN(I41)-LEN(SUBSTITUTE(I41,",",""))+1),IF(NOT(ISBLANK(I41)),LEN(I41)-LEN(SUBSTITUTE(I41,",",""))+2,1)) -> 1 | Z41: =IF(NOT(ISBLANK(Y41)),Y41-TODAY(),"") | AG41: =IF(AND(NOT(ISBLANK(K41)),NOT(ISBLANK(G41)),NOT(ISBLANK(O41)),NOT(ISBLANK(AB41)),AB41>0),(K41*G41*(O41/100))/AB41,0) -> 0 | AH41: =IF(T41="Yes","Tier 0: Emergency",IF(AG41>=100,"Tier 1: Fast Track",IF(AG41>=50,"Tier 2: Standard Delivery",IF(AG41>=10,"Tier 3: Custom Engagement","Tier 4: Backlog")))) -> Tier 4: Backlog | AI41: =IF(T41="Yes","Negative (Risk of Loss)",IF(L41="Retention/Risk of Loss","Negative (Risk of Loss)",IF(AND(K41>0,OR(L41="New Contract",L41="Expansion")),"Positive (New Revenue)","Neutral (Internal/Platform)"))) -> Neutral (Internal/Platform) | AJ41: =IF(NOT(ISBLANK(K41)),K41*(O41/100),0) -> 0 | AP41: =COUNTIF(Master_Data_JIRA_Tickets!I:I,B41) -> 0 | AS41: No | AT41: Not Started | AU41: No
B42: F-040 | C42: Trade Processing - 100% Accuracy Validation | D42: Trade Processing | E42: Platform Improvements | F42: Q1 2026 | G42: 5 | H42: Multiple | I42: 0 | J42: Platform Enhancement | X42: =IF(H42="Multiple",IF(ISBLANK(I42),1,LEN(I42)-LEN(SUBSTITUTE(I42,",",""))+1),IF(NOT(ISBLANK(I42)),LEN(I42)-LEN(SUBSTITUTE(I42,",",""))+2,1)) -> 1 | Z42: =IF(NOT(ISBLANK(Y42)),Y42-TODAY(),"") | AG42: =IF(AND(NOT(ISBLANK(K42)),NOT(ISBLANK(G42)),NOT(ISBLANK(O42)),NOT(ISBLANK(AB42)),AB42>0),(K42*G42*(O42/100))/AB42,0) -> 0 | AH42: =IF(T42="Yes","Tier 0: Emergency",IF(AG42>=100,"Tier 1: Fast Track",IF(AG42>=50,"Tier 2: Standard Delivery",IF(AG42>=10,"Tier 3: Custom Engagement","Tier 4: Backlog")))) -> Tier 4: Backlog | AI42: =IF(T42="Yes","Negative (Risk of Loss)",IF(L42="Retention/Risk of Loss","Negative (Risk of Loss)",IF(AND(K42>0,OR(L42="New Contract",L42="Expansion")),"Positive (New Revenue)","Neutral (Internal/Platform)"))) -> Neutral (Internal/Platform) | AJ42: =IF(NOT(ISBLANK(K42)),K42*(O42/100),0) -> 0 | AP42: =COUNTIF(Master_Data_JIRA_Tickets!I:I,B42) -> 0 | AS42: No | AT42: Not Started | AU42: No
B43: F-041 | C43: Security Settlements - Break Resolution Automation | D43: Security Settlements | E43: Platform Improvements | F43: Q2 2026 | G43: 5 | H43: Multiple | I43: 0 | J43: Platform Enhancement | X43: =IF(H43="Multiple",IF(ISBLANK(I43),1,LEN(I43)-LEN(SUBSTITUTE(I43,",",""))+1),IF(NOT(ISBLANK(I43)),LEN(I43)-LEN(SUBSTITUTE(I43,",",""))+2,1)) -> 1 | Z43: =IF(NOT(ISBLANK(Y43)),Y43-TODAY(),"") | AG43: =IF(AND(NOT(ISBLANK(K43)),NOT(ISBLANK(G43)),NOT(ISBLANK(O43)),NOT(ISBLANK(AB43)),AB43>0),(K43*G43*(O43/100))/AB43,0) -> 0 | AH43: =IF(T43="Yes","Tier 0: Emergency",IF(AG43>=100,"Tier 1: Fast Track",IF(AG43>=50,"Tier 2: Standard Delivery",IF(AG43>=10,"Tier 3: Custom Engagement","Tier 4: Backlog")))) -> Tier 4: Backlog | AI43: =IF(T43="Yes","Negative (Risk of Loss)",IF(L43="Retention/Risk of Loss","Negative (Risk of Loss)",IF(AND(K43>0,OR(L43="New Contract",L43="Expansion")),"Positive (New Revenue)","Neutral (Internal/Platform)"))) -> Neutral (Internal/Platform) | AJ43: =IF(NOT(ISBLANK(K43)),K43*(O43/100),0) -> 0 | AP43: =COUNTIF(Master_Data_JIRA_Tickets!I:I,B43) -> 0 | AS43: No | AT43: Not Started | AU43: No
B44: F-042 | C44: SSI - Real-time Data Validation | D44: Standing Settlement Instructions | E44: Platform Improvements | F44: Q1 2026 | G44: 5 | H44: Multiple | I44: 0 | J44: Platform Enhancement | X44: =IF(H44="Multiple",IF(ISBLANK(I44),1,LEN(I44)-LEN(SUBSTITUTE(I44,",",""))+1),IF(NOT(ISBLANK(I44)),LEN(I44)-LEN(SUBSTITUTE(I44,",",""))+2,1)) -> 1 | Z44: =IF(NOT(ISBLANK(Y44)),Y44-TODAY(),"") | AG44: =IF(AND(NOT(ISBLANK(K44)),NOT(ISBLANK(G44)),NOT(ISBLANK(O44)),NOT(ISBLANK(AB44)),AB44>0),(K44*G44*(O44/100))/AB44,0) -> 0 | AH44: =IF(T44="Yes","Tier 0: Emergency",IF(AG44>=100,"Tier 1: Fast Track",IF(AG44>=50,"Tier 2: Standard Delivery",IF(AG44>=10,"Tier 3: Custom Engagement","Tier 4: Backlog")))) -> Tier 4: Backlog | AI44: =IF(T44="Yes","Negative (Risk of Loss)",IF(L44="Retention/Risk of Loss","Negative (Risk of Loss)",IF(AND(K44>0,OR(L44="New Contract",L44="Expansion")),"Positive (New Revenue)","Neutral (Internal/Platform)"))) -> Neutral (Internal/Platform) | AJ44: =IF(NOT(ISBLANK(K44)),K44*(O44/100),0) -> 0 | AP44: =COUNTIF(Master_Data_JIRA_Tickets!I:I,B44) -> 0 | AS44: No | AT44: Not Started | AU44: No
B45: F-043 | C45: Matching Engine - External Break Detection | D45: Matching Engine | E45: Platform Improvements | F45: Q2 2026 | G45: 4 | H45: Multiple | I45: 0 | J45: Platform Enhancement | X45: =IF(H45="Multiple",IF(ISBLANK(I45),1,LEN(I45)-LEN(SUBSTITUTE(I45,",",""))+1),IF(NOT(ISBLANK(I45)),LEN(I45)-LEN(SUBSTITUTE(I45,",",""))+2,1)) -> 1 | Z45: =IF(NOT(ISBLANK(Y45)),Y45-TODAY(),"") | AG45: =IF(AND(NOT(ISBLANK(K45)),NOT(ISBLANK(G45)),NOT(ISBLANK(O45)),NOT(ISBLANK(AB45)),AB45>0),(K45*G45*(O45/100))/AB45,0) -> 0 | AH45: =IF(T45="Yes","Tier 0: Emergency",IF(AG45>=100,"Tier 1: Fast Track",IF(AG45>=50,"Tier 2: Standard Delivery",IF(AG45>=10,"Tier 3: Custom Engagement","Tier 4: Backlog")))) -> Tier 4: Backlog | AI45: =IF(T45="Yes","Negative (Risk of Loss)",IF(L45="Retention/Risk of Loss","Negative (Risk of Loss)",IF(AND(K45>0,OR(L45="New Contract",L45="Expansion")),"Positive (New Revenue)","Neutral (Internal/Platform)"))) -> Neutral (Internal/Platform) | AJ45: =IF(NOT(ISBLANK(K45)),K45*(O45/100),0) -> 0 | AP45: =COUNTIF(Master_Data_JIRA_Tickets!I:I,B45) -> 0 | AS45: No | AT45: Not Started | AU45: No
B46: F-044 | C46: One View - Cross-System Integration | D46: One View | E46: Platform Improvements | F46: Q2 2026 | G46: 5 | H46: Multiple | I46: 0 | J46: Platform Enhancement | X46: =IF(H46="Multiple",IF(ISBLANK(I46),1,LEN(I46)-LEN(SUBSTITUTE(I46,",",""))+1),IF(NOT(ISBLANK(I46)),LEN(I46)-LEN(SUBSTITUTE(I46,",",""))+2,1)) -> 1 | Z46: =IF(NOT(ISBLANK(Y46)),Y46-TODAY(),"") | AG46: =IF(AND(NOT(ISBLANK(K46)),NOT(ISBLANK(G46)),NOT(ISBLANK(O46)),NOT(ISBLANK(AB46)),AB46>0),(K46*G46*(O46/100))/AB46,0) -> 0 | AH46: =IF(T46="Yes","Tier 0: Emergency",IF(AG46>=100,"Tier 1: Fast Track",IF(AG46>=50,"Tier 2: Standard Delivery",IF(AG46>=10,"Tier 3: Custom Engagement","Tier 4: Backlog")))) -> Tier 4: Backlog | AI46: =IF(T46="Yes","Negative (Risk of Loss)",IF(L46="Retention/Risk of Loss","Negative (Risk of Loss)",IF(AND(K46>0,OR(L46="New Contract",L46="Expansion")),"Positive (New Revenue)","Neutral (Internal/Platform)"))) -> Neutral (Internal/Platform) | AJ46: =IF(NOT(ISBLANK(K46)),K46*(O46/100),0) -> 0 | AP46: =COUNTIF(Master_Data_JIRA_Tickets!I:I,B46) -> 0 | AS46: No | AT46: Not Started | AU46: No
B47: F-045 | C47: Loan Operations - Application Automation | D47: Loan Operations | E47: Platform Improvements | F47: Q3 2026 | G47: 4 | H47: Multiple | I47: 0 | J47: Platform Enhancement | X47: =IF(H47="Multiple",IF(ISBLANK(I47),1,LEN(I47)-LEN(SUBSTITUTE(I47,",",""))+1),IF(NOT(ISBLANK(I47)),LEN(I47)-LEN(SUBSTITUTE(I47,",",""))+2,1)) -> 1 | Z47: =IF(NOT(ISBLANK(Y47)),Y47-TODAY(),"") | AG47: =IF(AND(NOT(ISBLANK(K47)),NOT(ISBLANK(G47)),NOT(ISBLANK(O47)),NOT(ISBLANK(AB47)),AB47>0),(K47*G47*(O47/100))/AB47,0) -> 0 | AH47: =IF(T47="Yes","Tier 0: Emergency",IF(AG47>=100,"Tier 1: Fast Track",IF(AG47>=50,"Tier 2: Standard Delivery",IF(AG47>=10,"Tier 3: Custom Engagement","Tier 4: Backlog")))) -> Tier 4: Backlog | AI47: =IF(T47="Yes","Negative (Risk of Loss)",IF(L47="Retention/Risk of Loss","Negative (Risk of Loss)",IF(AND(K47>0,OR(L47="New Contract",L47="Expansion")),"Positive (New Revenue)","Neutral (Internal/Platform)"))) -> Neutral (Internal/Platform) | AJ47: =IF(NOT(ISBLANK(K47)),K47*(O47/100),0) -> 0 | AP47: =COUNTIF(Master_Data_JIRA_Tickets!I:I,B47) -> 0 | AS47: No | AT47: Not Started | AU47: No
B48: F-046 | C48: Core Reconciliation - Multi-System Support | D48: Core Reconciliation | E48: Platform Improvements | F48: Q1 2026 | G48: 5 | H48: Multiple | I48: 0 | J48: Platform Enhancement | X48: =IF(H48="Multiple",IF(ISBLANK(I48),1,LEN(I48)-LEN(SUBSTITUTE(I48,",",""))+1),IF(NOT(ISBLANK(I48)),LEN(I48)-LEN(SUBSTITUTE(I48,",",""))+2,1)) -> 1 | Z48: =IF(NOT(ISBLANK(Y48)),Y48-TODAY(),"") | AG48: =IF(AND(NOT(ISBLANK(K48)),NOT(ISBLANK(G48)),NOT(ISBLANK(O48)),NOT(ISBLANK(AB48)),AB48>0),(K48*G48*(O48/100))/AB48,0) -> 0 | AH48: =IF(T48="Yes","Tier 0: Emergency",IF(AG48>=100,"Tier 1: Fast Track",IF(AG48>=50,"Tier 2: Standard Delivery",IF(AG48>=10,"Tier 3: Custom Engagement","Tier 4: Backlog")))) -> Tier 4: Backlog | AI48: =IF(T48="Yes","Negative (Risk of Loss)",IF(L48="Retention/Risk of Loss","Negative (Risk of Loss)",IF(AND(K48>0,OR(L48="New Contract",L48="Expansion")),"Positive (New Revenue)","Neutral (Internal/Platform)"))) -> Neutral (Internal/Platform) | AJ48: =IF(NOT(ISBLANK(K48)),K48*(O48/100),0) -> 0 | AP48: =COUNTIF(Master_Data_JIRA_Tickets!I:I,B48) -> 0 | AS48: No | AT48: Not Started | AU48: No
B49: F-047 | C49: DeepPilot - Financial Services Context Mining | D49: DeepPilot | E49: Platform Improvements | F49: Q2 2026 | G49: 5 | H49: Multiple | I49: 0 | J49: Platform Enhancement | X49: =IF(H49="Multiple",IF(ISBLANK(I49),1,LEN(I49)-LEN(SUBSTITUTE(I49,",",""))+1),IF(NOT(ISBLANK(I49)),LEN(I49)-LEN(SUBSTITUTE(I49,",",""))+2,1)) -> 1 | Z49: =IF(NOT(ISBLANK(Y49)),Y49-TODAY(),"") | AG49: =IF(AND(NOT(ISBLANK(K49)),NOT(ISBLANK(G49)),NOT(ISBLANK(O49)),NOT(ISBLANK(AB49)),AB49>0),(K49*G49*(O49/100))/AB49,0) -> 0 | AH49: =IF(T49="Yes","Tier 0: Emergency",IF(AG49>=100,"Tier 1: Fast Track",IF(AG49>=50,"Tier 2: Standard Delivery",IF(AG49>=10,"Tier 3: Custom Engagement","Tier 4: Backlog")))) -> Tier 4: Backlog | AI49: =IF(T49="Yes","Negative (Risk of Loss)",IF(L49="Retention/Risk of Loss","Negative (Risk of Loss)",IF(AND(K49>0,OR(L49="New Contract",L49="Expansion")),"Positive (New Revenue)","Neutral (Internal/Platform)"))) -> Neutral (Internal/Platform) | AJ49: =IF(NOT(ISBLANK(K49)),K49*(O49/100),0) -> 0 | AP49: =COUNTIF(Master_Data_JIRA_Tickets!I:I,B49) -> 0 | AS49: No | AT49: Not Started | AU49: No

Sheet Master_Data_JIRA_Tickets
A1: jira_ticket_id | B1: jira_ticket_title | C1: jira_status | D1: jira_category | E1: project_key | F1: client_name | G1: effort_tshirt_size | H1: story_points | I1: mapped_feature_id | J1: mapped_feature_name | K1: assigned_engineer | L1: sprint | M1: created_date | N1: target_date | O1: completed_date
A2: PR-1555 | B2: Enable Conditional Reconciliation | C2: New | D2: Product Roadmap | E2: PR | M2: 45973
A3: UI-694 | B3: UI and Dashboard Improvements to DeepRecon to Support Boradridge | C3: To Do | D3: Front End Development | E3: UI | M3: 45972
A4: BACK-1481 | B4: PDF Conversion fails for PNG files | C4: To Do | D4: Back End Development | E4: BACK | M4: 45972
A5: UI-693 | B5: Add a new blockly block to use equivalency lists on full strings | C5: To Do | D5: Front End Development | E5: UI | M5: 45972
A6: UI-692 | B6: Allow filtering and sorting by custom fields in Actionable data | C6: To Do | D6: Front End Development | E6: UI | M6: 45972
A7: UI-691 | B7: Display Custom fields in Actionable Data | C7: To Do | D7: Front End Development | E7: UI | M7: 45972
A8: UI-690 | B8: Allow the user to create custom fields when configuring Automations | C8: To Do | D8: Front End Development | E8: UI | M8: 45972
A9: UI-689 | B9: Implement Custom fields (key-value pairs) for Deep Recon | C9: To Do | D9: Front End Development | E9: UI | M9: 45972
A10: UI-688 | B10: Deploy the latest UI image to FIS Tenant | C10: To Do | D10: Front End Development | E10: UI | M10: 45972
A11: UI-687 | B11: UI - Configure FIS Tenant | C11: To Do | D11: Front End Development | E11: UI | M11: 45972
A12: CI-894 | B12: Create Tenant for FIS - US region | C12: To Do | D12: Core-Infrastructure | E12: CI | M12: 45972
A13: CI-893 | B13: Infra - Configure Tenant for FIS | C13: To Do | D13: Core-Infrastructure | E13: CI | M13: 45972
A14: BACK-1480 | B14: Integrate CrowdStrike security scanning into CI/CD pipeline for Extraction service | C14: In Progress | D14: Back End Development | E14: BACK | K14: Kalvin Willison | M14: 45972
A15: PR-1553 | B15: Set Up/Configure FIS Tenant | C15: Planning | D15: Product Roadmap | E15: PR | M15: 45972
A16: CI-892 | B16: Create Tenant for BBVA - EU region | C16: To Do | D16: Core-Infrastructure | E16: CI | M16: 45971
A17: CI-891 | B17: Infra - Configure Tenant for BBVA | C17: To Do | D17: Core-Infrastructure | E17: CI | M17: 45971
A18: UI-686 | B18: Deploy the latest UI image to BBVA Tenant | C18: To Do | D18: Front End Development | E18: UI | M18: 45971
A19: UI-685 | B19: Configure BBVA Tenant | C19: To Do | D19: Front End Development | E19: UI | M19: 45971
A20: CI-890 | B20: Create Tenant for CTC for EU region | C20: To Do | D20: Core-Infrastructure | E20: CI | M20: 45971
A21: CI-889 | B21: Infra - Configure Tenant for CTC | C21: To Do | D21: Core-Infrastructure | E21: CI | M21: 45971
A22: UI-684 | B22: Deploy the latest UI image to CTC Tenant | C22: To Do | D22: Front End Development | E22: UI | M22: 45971
A23: UI-683 | B23: UI - Configure CTC Tenant | C23: To Do | D23: Front End Development | E23: UI | M23: 45971
A24: PR-1552 | B24: Set Up/Configure BBVA Tenant | C24: Planning | D24: Product Roadmap | E24: PR | M24: 45971
A25: PR-1551 | B25: Set Up/Configure CTC Tenant | C25: Planning | D25: Product Roadmap | E25: PR | M25: 45971
A26: SC-299 | B26: Priority: Address Wiz-Identified Assets (13 Assets, 390 C+H) | C26: To Do | D26: Security & Compliance | E26: SC | M26: 45967
A27: UI-682 | B27: Enhance "Golden Source" Picker for Colony Bank | C27: In Progress | D27: Front End Development | E27: UI | H27: 2 | K27: Owen Riley | M27: 45966
A28: UI-681 | B28: Allow for Document Orientation Adjustment | C28: To Do | D28: Front End Development | E28: UI | M28: 45966
A29: BACK-1477 | B29: Configure the API key for the news sources | C29: To Do | D29: Back End Development | E29: BACK | M29: 45966
A30: CI-887 | B30: Helm chart changes for new k8s job | C30: To Do | D30: Core-Infrastructure | E30: CI | M30: 45966
A31: CI-886 | B31: Update Terraform for the new k8s job | C31: To Do | D31: Core-Infrastructure | E31: CI | M31: 45966
A32: BACK-1474 | B32: Create a scheduled data fetch k8s job | C32: To Do | D32: Back End Development | E32: BACK | M32: 45966
A33: BACK-1472 | B33: Add user defined key-value pairs that can be associated with a message | C33: To Do | D33: Back End Development | E33: BACK | H33: 5 | M33: 45965
A34: BACK-1471 | B34: Add Custom Fields in Deep Recon | C34: To Do | D34: Back End Development | E34: BACK | M34: 45965
A35: BACK-1470 | B35: Update the prediction API to include custom fields | C35: To Do | D35: Back End Development | E35: BACK | H35: 3 | M35: 45965
A36: BACK-1469 | B36: Allow Automation to use custom fields | C36: To Do | D36: Back End Development | E36: BACK | H36: 6 | M36: 45965
A37: BACK-1468 | B37: Use equivalency lists on full strings | C37: To Do | D37: Back End Development | E37: BACK | H37: 3 | M37: 45965
A38: BACK-1467 | B38: Create a custom FEEL function that would use equivalency lists and a string | C38: Canceled | D38: Back End Development | E38: BACK | M38: 45965
A39: BACK-1466 | B39: FEEL / Equivalency matching improvements to build Automations for Accenture | C39: To Do | D39: Back End Development | E39: BACK | M39: 45965
A40: UI-678 | B40: Create Absolute Value Puzzle Piece | C40: Code Review | D40: Front End Development | E40: UI | H40: 2 | K40: Owen Riley | M40: 45965
...

Sheet Master_Data_Sales_Pipeline
B2: Opportunity_ID | C2: Opportunity_Name | D2: Account_Name | E2: Stage | F2: ARR_Value | G2: Close_Date | H2: Probability_% | I2: Owner | J2: Agent_Type | K2: Mapped_Feature_ID | L2: Status | M2: Created_Date | N2: Last_Activity_Date | O2: Notes | P2: Weighted_ARR | Q2: Days_in_Stage
B3: OPP-001 | C3: DTCC Trade Processing POC to Production | D3: DTCC | E3: Closed Won | F3: 750000 | G3: 2025-12-31 | H3: 1 | I3: Steve Shillingford | J3: Trade Processing | K3: F-026 | L3: Active | M3: 2025-06-15 | N3: 2025-10-31 | P3: =F3*(H3/100) -> 7500 | Q3: =IF(NOT(ISBLANK(N3)),TODAY()-N3,"") -> 8
B4: OPP-002 | C4: Broadridge Email Automation Expansion | D4: Broadridge | E4: Closed Won | F4: 500000 | G4: 2025-11-30 | H4: 1 | I4: Steve Shillingford | J4: Email Automation | K4: F-030 | L4: Active | M4: 2025-07-01 | N4: 2025-10-15 | P4: =F4*(H4/100) -> 5000 | Q4: =IF(NOT(ISBLANK(N4)),TODAY()-N4,"") -> 24
B5: OPP-003 | C5: Colony Bank SSI Deployment | D5: Regional Banks - Colony Bank | E5: Closed Won | F5: 200000 | G5: 2025-12-15 | H5: 1 | I5: Armen Sargysan | J5: Standing Settlement Instructions | K5: F-036 | L5: Active | M5: 2025-08-01 | N5: 2025-11-01 | P5: =F5*(H5/100) -> 2000 | Q5: =IF(NOT(ISBLANK(N5)),TODAY()-N5,"") -> 7
B6: OPP-004 | C6: Accenture Multi-Agent Platform | D6: Accenture | E6: Closed Won | F6: 1200000 | G6: 2025-10-31 | H6: 1 | I6: Steve Shillingford | J6: Platform (All Agents) | K6: F-034, F-035 | L6: Active | M6: 2025-05-01 | N6: 2025-10-25 | P6: =F6*(H6/100) -> 12000 | Q6: =IF(NOT(ISBLANK(N6)),TODAY()-N6,"") -> 14
B7: OPP-005 | C7: JP Morgan Reconciliation Annual Renewal | D7: JP Morgan | E7: Closed Won | F7: 3000000 | G7: 2025-12-31 | H7: 1 | I7: Steve Shillingford | J7: Core Reconciliation | K7: F-032 | L7: Renewal | M7: 2024-12-01 | N7: 2025-11-05 | P7: =F7*(H7/100) -> 30000 | Q7: =IF(NOT(ISBLANK(N7)),TODAY()-N7,"") -> 3
B8: OPP-006 | C8: Sunwest Bank SSI Deployment | D8: Regional Banks - Sunwest Bank | E8: Contract Negotiation | F8: 180000 | G8: 2026-01-31 | H8: 0.8 | I8: Armen Sargysan | J8: Standing Settlement Instructions | K8: F-037 | L8: Active | M8: 2025-09-01 | N8: 2025-11-05 | P8: =F8*(H8/100) -> 1440 | Q8: =IF(NOT(ISBLANK(N8)),TODAY()-N8,"") -> 3
B9: OPP-007 | C9: Large Bank Trade Processing Platform | D9: [Confidential - Large US Bank] | E9: Contract Negotiation | F9: 2500000 | G9: 2026-02-28 | H9: 0.8 | I9: Steve Shillingford | J9: Trade Processing | K9: F-040 | L9: Active | M9: 2025-07-15 | N9: 2025-11-06 | P9: =F9*(H9/100) -> 20000 | Q9: =IF(NOT(ISBLANK(N9)),TODAY()-N9,"") -> 2
B10: OPP-008 | C10: Vantage Bank Custom Reconciliation POC | D10: Regional Banks - Vantage Bank | E10: POC | F10: 200000 | G10: 2026-03-31 | H10: 0.5 | I10: Armen Sargysan | J10: Core Reconciliation | K10: F-038 | L10: At Risk | M10: 2025-08-15 | N10: 2025-10-30 | O10: Client tired of waiting, requires prepayment or binding contract | P10: =F10*(H10/100) -> 1000 | Q10: =IF(NOT(ISBLANK(N10)),TODAY()-N10,"") -> 9
B11: OPP-009 | C11: Insurance Company Loan Operations | D11: [Prospect - Insurance Co A] | E11: POC | F11: 600000 | G11: 2026-04-30 | H11: 0.6 | I11: Armen Sargysan | J11: Loan Operations | K11: F-045 | L11: Active | M11: 2025-09-01 | N11: 2025-11-04 | P11: =F11*(H11/100) -> 3600 | Q11: =IF(NOT(ISBLANK(N11)),TODAY()-N11,"") -> 4
B12: OPP-010 | C12: Asset Manager Email Automation | D12: [Prospect - Asset Manager B] | E12: POC | F12: 400000 | G12: 2026-03-31 | H12: 0.6 | I12: Armen Sargysan | J12: Email Automation | K12: F-039 | L12: Active | M12: 2025-09-15 | N12: 2025-11-03 | P12: =F12*(H12/100) -> 2400 | Q12: =IF(NOT(ISBLANK(N12)),TODAY()-N12,"") -> 5
B13: OPP-011 | C13: Regional Bank Consortium Platform | D13: [Prospect - Regional Bank Consortium] | E13: Proposal | F13: 800000 | G13: 2026-05-31 | H13: 0.5 | I13: Steve Shillingford | J13: Platform (All Agents) | K13: Multiple platform features | L13: Active | M13: 2025-09-01 | N13: 2025-10-28 | P13: =F13*(H13/100) -> 4000 | Q13: =IF(NOT(ISBLANK(N13)),TODAY()-N13,"") -> 11
B14: OPP-012 | C14: Hedge Fund Trade Matching | D14: [Prospect - Hedge Fund D] | E14: Proposal | F14: 350000 | G14: 2026-04-30 | H14: 0.5 | I14: Armen Sargysan | J14: Matching Engine | K14: F-043 | L14: Active | M14: 2025-10-01 | N14: 2025-11-01 | P14: =F14*(H14/100) -> 1750 | Q14: =IF(NOT(ISBLANK(N14)),TODAY()-N14,"") -> 7
B15: OPP-013 | C15: Global Bank Security Settlements | D15: [Prospect - Global Bank E] | E15: Qualification | F15: 1500000 | G15: 2026-06-30 | H15: 0.3 | I15: Steve Shillingford | J15: Security Settlements | K15: F-041 | L15: Active | M15: 2025-10-01 | N15: 2025-11-02 | P15: =F15*(H15/100) -> 4500 | Q15: =IF(NOT(ISBLANK(N15)),TODAY()-N15,"") -> 6
B16: OPP-014 | C16: Investment Bank One View Platform | D16: [Prospect - Investment Bank F] | E16: Qualification | F16: 900000 | G16: 2026-07-31 | H16: 0.3 | I16: Armen Sargysan | J16: One View | K16: F-044 | L16: Active | M16: 2025-10-15 | N16: 2025-10-31 | P16: =F16*(H16/100) -> 2700 | Q16: =IF(NOT(ISBLANK(N16)),TODAY()-N16,"") -> 8
B17: OPP-015 | C17: European Bank Multi-Agent Exploration | D17: [Prospect - European Bank G] | E17: Introduction | F17: 2000000 | G17: 2026-09-30 | H17: 0.1 | I17: Steve Shillingford | J17: Platform (All Agents) | K17: Multiple platform features | L17: Early Stage | M17: 2025-10-20 | N17: 2025-10-25 | P17: =F17*(H17/100) -> 2000 | Q17: =IF(NOT(ISBLANK(N17)),TODAY()-N17,"") -> 14
B18: OPP-016 | C18: Pension Fund DeepPilot Discussion | D18: [Prospect - Pension Fund H] | E18: Introduction | F18: 500000 | G18: 2026-08-31 | H18: 0.1 | I18: Armen Sargysan | J18: DeepPilot | K18: F-047 | L18: Early Stage | M18: 2025-10-25 | N18: 2025-10-28 | P18: =F18*(H18/100) -> 500 | Q18: =IF(NOT(ISBLANK(N18)),TODAY()-N18,"") -> 11

Sheet Lookup_Tables
B2: Clients | D2: Agent_Types | F2: Pipeline_Stages | H2: Priority_Tiers | J2: Categories | L2: Team_Assignment | N2: Status_Options | P2: Revenue_Types | R2: Contract_Status | T2: Yes_No_Options | V2: PRD_Status_Options
B3: Broadridge | D3: Email Automation | F3: Introduction | H3: Tier 0: Emergency | J3: Core Infrastructure | L3: Frontend | N3: Not Started | P3: New Contract | R3: Signed | T3: Yes | V3: Complete
B4: DTCC | D4: Trade Processing | F4: Qualification | H4: Tier 1: Fast Track | J4: Client-Specific Work | L4: Backend | N4: In Progress | P4: Expansion | R4: Verbal Commitment | T4: No | V4: In Progress
B5: JP Morgan | D5: Security Settlements | F5: Proposal | H5: Tier 2: Standard Delivery | J5: Platform Improvements | L5: DevOps | N5: Blocked | P5: Retention/Risk of Loss | R5: POC | V5: Not Started
B6: Accenture | D6: Standing Settlement Instructions | F6: POC | H6: Tier 3: Custom Engagement | J6: API Development | L6: ML (Machine Learning) | N6: Completed | P6: Internal | R6: Exploratory | V6: N/A
B7: Regional Banks | D7: Matching Engine | F7: Contract Negotiation | H7: Tier 4: Backlog | J7: Bug Fixes | L7: Multiple Teams | N7: Cancelled
B8: Multiple | D8: One View | F8: Closed Won
B9: Internal | D9: Loan Operations | F9: Closed Lost
D10: Core Reconciliation
D11: DeepPilot
D12: Platform (All Agents)
D13: Platform (Analytics)

Sheet Master_Data_Client_Projects
B2: Project_ID | C2: Client_Name | D2: Project_Name | E2: Status | F2: Start_Date | G2: End_Date | H2: Project_Value | I2: Features_Required | J2: Mapped_Feature_IDs
B3: PROJ-001 | C3: DTCC | D3: DTCC Phase 1 Onboarding | E3: In Progress | F3: 2025-10-01 | G3: 2025-12-31 | H3: 750000 | I3: Trade Processing Agent, Core Reconciliation | J3: F-026, F-028
B4: PROJ-002 | C4: Broadridge | D4: Broadridge Email Automation Expansion | E4: In Progress | F4: 2025-09-01 | G4: 2025-11-30 | H4: 500000 | I4: Email Automation, Trade Processing Enhancement | J4: F-030, F-029
B5: PROJ-003 | C5: Regional Banks | D5: Colony Bank SSI Deployment | E5: In Progress | F5: 2025-11-01 | G5: 2025-12-15 | H5: 200000 | I5: SSI Agent | J5: F-036
B6: PROJ-004 | C6: Accenture | D6: Accenture Multi-Agent Platform | E6: In Progress | F6: 2025-08-01 | G6: 2026-02-28 | H6: 1200000 | I6: Multi-agent orchestration, Email Automation | J6: F-034, F-035
B7: PROJ-005 | C7: JP Morgan | D7: JP Morgan Annual Contract | E7: Active | F7: 2024-01-01 | G7: 2025-12-31 | H7: 3000000 | I7: Core Reconciliation, Security Settlements | J7: F-032, F-033

Sheet Master_Data_Won_Deals
B2: Client_Name | C2: Original_Contract_Value | D2: Renewal_Date | E2: Upsell_Opportunity | F2: Potential_Expansion_ARR | G2: Risk_Level
B3: DTCC | C3: 750000 | D3: 2026-12-31 | E3: Additional agents (Security Settlements, SSI) | F3: 400000 | G3: Low
B4: Broadridge | C4: 500000 | D4: 2026-11-30 | E4: Trade Processing + Email Automation expansion | F4: 300000 | G4: Medium (recent bug fix required)
B5: JP Morgan | C5: 3000000 | D5: 2026-12-31 | E5: Platform expansion, additional asset classes | F5: 500000 | G5: Low
B6: Accenture | C6: 1200000 | D6: 2026-10-31 | E6: New use cases, additional agents | F6: 800000 | G6: Low
B7: Colony Bank | C7: 200000 | D7: 2026-12-15 | E7: Additional regional banks | F7: 180000 | G7: Low

Sheet Scoring_Rubric
B2: DEEP SEE AI - SCORING RUBRIC & FORMULAS
B4: PRIORITY SCORE FORMULA:
B5: Priority_Score = (ARR_Amount × Replicability_Score × Conversion_Probability_%) / Effort_Estimate_Weeks
B7: Example Calculation:
B8: • ARR: $200,000
B9: • Replicability: 5 (all clients benefit)
B10: • Conversion Probability: 100%
B11: • Effort: 6 weeks
B12: • Priority_Score = (200,000 × 5 × 100%) / 6 = 166,667 → Tier 1: Fast Track
B14: TIER ASSIGNMENT LOGIC:
B15: Tier | C15: Criteria | D15: Description
B16: Tier 0: Emergency | C16: Revenue_at_Risk = 'Yes' | D16: Negative Revenue (client threatening to leave)
B17: Tier 1: Fast Track | C17: Priority_Score >= 100 | D17: High-value, replicable, high-probability
B18: Tier 2: Standard Delivery | C18: Priority_Score 50-99 | D18: Medium priority work
B19: Tier 3: Custom Engagement | C19: Priority_Score 10-49 | D19: Lower priority, often custom
B20: Tier 4: Backlog | C20: Priority_Score < 10 | D20: Low priority or exploratory
B22: CONVERSION PROBABILITY MAPPING:
B23: Pipeline Stage | C23: Probability
B24: Introduction | C24: 10%
B25: Qualification | C25: 30%
B26: Proposal | C26: 50%
B27: POC | C27: 60%
B28: Contract Negotiation | C28: 80%
B29: Closed Won | C29: 100%
B30: Closed Lost | C30: 0%
B32: REPLICABILITY SCORE (1-5):
B33: Score | C33: Definition
B34: 1 | C34: One-off custom build (single client only)
B35: 2 | C35: Somewhat custom (minimal reuse potential)
B36: 3 | C36: Approximately half of clients benefit
B37: 4 | C37: Most clients benefit
B38: 5 | C38: All clients benefit (platform enhancement)
B40: EFFORT T-SHIRT SIZING:
B41: Size | C41: Weeks
B42: S (Small) | C42: 2 weeks
B43: M (Medium) | C43: 4 weeks
B44: L (Large) | C44: 8 weeks
B45: XL (Extra Large) | C45: 12+ weeks
B47: EMERGENCY BUFFER RULE:
B48: • Each sprint: 80% committed work (Tier 1-2), 20% emergency buffer (Tier 0)
...

Sheet README_Instructions
B2: DEEP SEE AI UNIFIED PRIORITIZATION SYSTEM - INSTRUCTIONS
B4: FOR STEVE (Sales/CEO):
B5: Your role: Validate revenue and conversion data
B6: Steps:
B7: 1. Go to Tab: Master_Data_Features
B8: 2. Review columns: ARR_Amount, Revenue_Type, Contract_Status, Revenue_at_Risk, Conversion_Probability_%
B9: 3. To override Priority_Score: Enter your score in Manual_Override_Score column
B10: 4. Add context in Management_Notes column
B11: 5. View your dashboard: PIVOT - Management View
B12: Time Required: ~2 hours initial setup, <30 min weekly maintenance
B14: FOR RYAN (Product):
B15: Your role: Validate product features and replicability
... B49: TABS GUIDE:
B50: Tab Name | C50: Purpose
B51: Master_Data_Features | C51: 47 product features with prioritization
B52: Master_Data_JIRA_Tickets | C52: 198 engineering tickets mapped to features
B53: Master_Data_Sales_Pipeline | C53: 16 sales opportunities
B54: Master_Data_Client_Projects | C54: 5 active client projects
B55: Master_Data_Won_Deals | C55: 5 won deals & renewal tracking
B56: Lookup_Tables | C56: Reference data for dropdowns
B57: Scoring_Rubric | C57: Formula documentation
B58: README_Instructions | C58: This tab - user guide
B60: ARTEMIS STRATEGIC TRACKING (NEW):
B61: Ryan (Product) - Use these columns to track strategic platform work:
B62: • Artemis_Focus: Mark 'Yes' for strategic platform rebuild features
B63: • PRD_Status: Track PRD completion (Complete, In Progress, Not Started, N/A)
B64: • Epic_in_JIRA: Mark 'Yes' when epic is logged in JIRA
B65: 0
B66: View Strategic Balance:
B67: • Executive Dashboard - Shows Artemis vs Operational split
B68: • PIVOT_Strategic_vs_Operational - Detailed analysis by tier and PRD status
B69: 0
B70: Key Insight: Balance immediate revenue ($2.5M operational) vs platform scaling (Artemis)

Sheet Change_Log
B2: Date | C2: User | D2: Feature_ID | E2: Field_Changed | F2: Old_Value | G2: New_Value | H2: Reason_for_Change
B3: 2025-11-08 | C3: Steve Shillingford | D3: F-038 | E3: Conversion_Probability_% | F3: 60% | G3: 30% | H3: Vantage Bank losing interest, lowering conversion estimate

Sheet Executive_Dashboard
B2: EXECUTIVE SUMMARY DASHBOARD
B4: KEY PERFORMANCE INDICATORS
D6: Total ARR in Pipeline | F6: Total ARR at Risk | H6: Total Features | J6: Features Completed Q4
